Workbook
Name UPDATE: 'Data Sheet'!$E$1

Sheet Ratio Analysis
B2: ="Ratio Analysis - "&'Data Sheet'!B1 -> Ratio Analysis - EICHER MOTORS LTD
B3: Years | D3: ='Financial Statment Analysi'!D5 -> 43921 | E3: ='Financial Statment Analysi'!E5 -> 44286 | F3: ='Financial Statment Analysi'!F5 -> 44651 | G3: ='Financial Statment Analysi'!G5 -> 45016 | H3: ='Financial Statment Analysi'!H5 -> 45382 | I3: ='Financial Statment Analysi'!I5 -> 45747 | J3: Trend | K3: Mean | L3: Median
B5: Sales Growth | E5: ='Financial Statment Analysi'!E9 -> -0.047329023 | F5: ='Financial Statment Analysi'!F9 -> 0.18089641 | G5: ='Financial Statment Analysi'!G9 -> 0.40244887 | H5: ='Financial Statment Analysi'!H9 -> 0.14496426 | I5: ='Financial Statment Analysi'!I9 -> 0.14118294 | K5: =IFERROR(AVERAGE(E5:I5),0) -> 0.16443269 | L5: =IFERROR(MEDIAN(D5:I5),0) -> 0.14496426
B6: EBITDA Growth | E6: =IFERROR('Financial Statment Analysi'!E20/'Financial Statment Analysi'!D20-1,0) -> -0.18308756 | F6: =IFERROR('Financial Statment Analysi'!F20/'Financial Statment Analysi'!E20-1,0) -> 0.22113805 | G6: =IFERROR('Financial Statment Analysi'!G20/'Financial Statment Analysi'!F20-1,0) -> 0.58236934 | H6: =IFERROR('Financial Statment Analysi'!H20/'Financial Statment Analysi'!G20-1,0) -> 0.25644858 | I6: =IFERROR('Financial Statment Analysi'!I20/'Financial Statment Analysi'!H20-1,0) -> 0.090821528 | K6: =IFERROR(AVERAGE(E6:I6),0) -> 0.19353799 | L6: =IFERROR(MEDIAN(D6:I6),0) -> 0.22113805
B7: EBIT Growth | E7: =IFERROR('Financial Statment Analysi'!E29/'Financial Statment Analysi'!D29-1,0) -> -0.2616706 | F7: =IFERROR('Financial Statment Analysi'!F29/'Financial Statment Analysi'!E29-1,0) -> 0.2969568 | G7: =IFERROR('Financial Statment Analysi'!G29/'Financial Statment Analysi'!F29-1,0) -> 0.69404052 | H7: =IFERROR('Financial Statment Analysi'!H29/'Financial Statment Analysi'!G29-1,0) -> 0.27300803 | I7: =IFERROR('Financial Statment Analysi'!I29/'Financial Statment Analysi'!H29-1,0) -> 0.070094461 | K7: =IFERROR(AVERAGE(E7:I7),0) -> 0.21448584 | L7: =IFERROR(MEDIAN(D7:I7),0) -> 0.27300803
B8: Net Profit Growth | E8: =IFERROR('Financial Statment Analysi'!E35/'Financial Statment Analysi'!D35-1,0) -> -0.31112652 | F8: =IFERROR('Financial Statment Analysi'!F35/'Financial Statment Analysi'!E35-1,0) -> 0.36597074 | G8: =IFERROR('Financial Statment Analysi'!G35/'Financial Statment Analysi'!F35-1,0) -> 0.6984631 | H8: =IFERROR('Financial Statment Analysi'!H35/'Financial Statment Analysi'!G35-1,0) -> 0.23635457 | I8: =IFERROR('Financial Statment Analysi'!I35/'Financial Statment Analysi'!H35-1,0) -> 0.10500105 | K8: =IFERROR(AVERAGE(E8:I8),0) -> 0.21893259 | L8: =IFERROR(MEDIAN(D8:I8),0) -> 0.23635457
B9: Dividend Growth | E9: =IFERROR('Financial Statment Analysi'!E43/'Financial Statment Analysi'!D43-1,0) -> 0.36049817 | F9: =IFERROR('Financial Statment Analysi'!F43/'Financial Statment Analysi'!E43-1,0) -> 0.23529412 | G9: =IFERROR('Financial Statment Analysi'!G43/'Financial Statment Analysi'!F43-1,0) -> 0.76190476 | H9: =IFERROR('Financial Statment Analysi'!H43/'Financial Statment Analysi'!G43-1,0) -> 0.37837838 | I9: =IFERROR('Financial Statment Analysi'!I43/'Financial Statment Analysi'!H43-1,0) -> 0.37254902 | K9: =IFERROR(AVERAGE(E9:I9),0) -> 0.42172489 | L9: =IFERROR(MEDIAN(D9:I9),0) -> 0.37254902
B11: Gross Margin | D11: =IFERROR('Financial Statment Analysi'!D15,0) -> 0.33207663 | E11: =IFERROR('Financial Statment Analysi'!E15,0) -> 0.28202308 | F11: =IFERROR('Financial Statment Analysi'!F15,0) -> 0.30394073 | G11: =IFERROR('Financial Statment Analysi'!G15,0) -> 0.32905559 | H11: =IFERROR('Financial Statment Analysi'!H15,0) -> 0.35285907 | I11: =IFERROR('Financial Statment Analysi'!I15,0) -> 0.35130456 | K11: =IFERROR(AVERAGE(D11:I11),0) -> 0.32520994 | L11: =IFERROR(MEDIAN(D11:I11),0) -> 0.33056611
B12: EBITDA Margin | D12: =IFERROR('Financial Statment Analysi'!D21,0) -> 0.23847391 | E12: =IFERROR('Financial Statment Analysi'!E21,0) -> 0.20449065 | F12: =IFERROR('Financial Statment Analysi'!F21,0) -> 0.21145911 | G12: =IFERROR('Financial Statment Analysi'!G21,0) -> 0.23858725 | H12: =IFERROR('Financial Statment Analysi'!H21,0) -> 0.26181831 | I12: =IFERROR('Financial Statment Analysi'!I21,0) -> 0.25026404 | K12: =IFERROR(AVERAGE(D12:I12),0) -> 0.23418221 | L12: =IFERROR(MEDIAN(D12:I12),0) -> 0.23853058
B13: EBIT Margin | D13: =IFERROR(('Financial Statment Analysi'!D20-'Financial Statment Analysi'!D26)/'Financial Statment Analysi'!D8,0) -> 0.19679186 | E13: =IFERROR(('Financial Statment Analysi'!E20-'Financial Statment Analysi'!E26)/'Financial Statment Analysi'!E8,0) -> 0.1528035 | F13: =IFERROR(('Financial Statment Analysi'!F20-'Financial Statment Analysi'!F26)/'Financial Statment Analysi'!F8,0) -> 0.16757317 | G13: =IFERROR(('Financial Statment Analysi'!G20-'Financial Statment Analysi'!G26)/'Financial Statment Analysi'!G8,0) -> 0.20215161 | H13: =IFERROR(('Financial Statment Analysi'!H20-'Financial Statment Analysi'!H26)/'Financial Statment Analysi'!H8,0) -> 0.2256785 | I13: =IFERROR(('Financial Statment Analysi'!I20-'Financial Statment Analysi'!I26)/'Financial Statment Analysi'!I8,0) -> 0.21161452 | K13: =IFERROR(AVERAGE(D13:I13),0) -> 0.19276886 | L13: =IFERROR(MEDIAN(D13:I13),0) -> 0.19947174
B14: EBT Margin | D14: =IFERROR('Financial Statment Analysi'!D30,0) -> 0.19472928 | E14: =IFERROR('Financial Statment Analysi'!E30,0) -> 0.15091711 | F14: =IFERROR('Financial Statment Analysi'!F30,0) -> 0.16574948 | G14: =IFERROR('Financial Statment Analysi'!G30,0) -> 0.20021146 | H14: =IFERROR('Financial Statment Analysi'!H30,0) -> 0.22260153 | I14: =IFERROR('Financial Statment Analysi'!I30,0) -> 0.20873487 | K14: =IFERROR(AVERAGE(D14:I14),0) -> 0.19049062 | L14: =IFERROR(MEDIAN(D14:I14),0) -> 0.19747037
B15: Net Profit Margin | D15: =IFERROR('Financial Statment Analysi'!D36,0) -> 0.13710701 | E15: =IFERROR('Financial Statment Analysi'!E36,0) -> 0.099141663 | F15: =IFERROR('Financial Statment Analysi'!F36,0) -> 0.1146795 | G15: =IFERROR('Financial Statment Analysi'!G36,0) -> 0.13888485 | H15: =IFERROR('Financial Statment Analysi'!H36,0) -> 0.14997055 | I15: =IFERROR('Financial Statment Analysi'!I36,0) -> 0.14521564 | K15: =IFERROR(AVERAGE(D15:I15),0) -> 0.1308332 | L15: =IFERROR(MEDIAN(D15:I15),0) -> 0.13799593
B17: Sales Expense % Sales | D17: =IFERROR('Financial Statment Analysi'!D18,0) -> 0.093602722 | E17: =IFERROR('Financial Statment Analysi'!E18,0) -> 0.077532438 | F17: =IFERROR('Financial Statment Analysi'!F18,0) -> 0.09248162 | G17: =IFERROR('Financial Statment Analysi'!G18,0) -> 0.090468336 | H17: =IFERROR('Financial Statment Analysi'!H18,0) -> 0.091040761 | I17: =IFERROR('Financial Statment Analysi'!I18,0) -> 0.10104052 | K17: =IFERROR(AVERAGE(D17:I17),0) -> 0.091027733 | L17: =IFERROR(MEDIAN(D17:I17),0) -> 0.091761191
B18: Depreciation % Sales | D18: =IFERROR('Financial Statment Analysi'!D27,0) -> 0.041682052 | E18: =IFERROR('Financial Statment Analysi'!E27,0) -> 0.051687146 | F18: =IFERROR('Financial Statment Analysi'!F27,0) -> 0.043885945 | G18: =IFERROR('Financial Statment Analysi'!G27,0) -> 0.036435635 | H18: =IFERROR('Financial Statment Analysi'!H27,0) -> 0.036139813 | I18: =IFERROR('Financial Statment Analysi'!I27,0) -> 0.038649522 | K18: =IFERROR(AVERAGE(D18:I18),0) -> 0.041413352 | L18: =IFERROR(MEDIAN(D18:I18),0) -> 0.040165787
B19: Operating Income % Sales | D19: =D13 -> 0.19679186 | E19: =E13 -> 0.1528035 | F19: =F13 -> 0.16757317 | G19: =G13 -> 0.20215161 | H19: =H13 -> 0.2256785 | I19: =I13 -> 0.21161452 | K19: =IFERROR(AVERAGE(D19:I19),0) -> 0.19276886 | L19: =IFERROR(MEDIAN(D19:I19),0) -> 0.19947174
B21: Returned on Capital Employed | D21: =IFERROR(('Financial Statment Analysi'!D20-'Financial Statment Analysi'!D26)/(SUM('Financial Statment Analysi'!D51:D53)),0) -> 0.17608625 | E21: =('Financial Statment Analysi'!E20-'Financial Statment Analysi'!E26)/(SUM('Financial Statment Analysi'!E51:E53)) -> 0.11430576 | F21: =('Financial Statment Analysi'!F20-'Financial Statment Analysi'!F26)/(SUM('Financial Statment Analysi'!F51:F53)) -> 0.13570929 | G21: =('Financial Statment Analysi'!G20-'Financial Statment Analysi'!G26)/(SUM('Financial Statment Analysi'!G51:G53)) -> 0.19108379 | H21: =('Financial Statment Analysi'!H20-'Financial Statment Analysi'!H26)/(SUM('Financial Statment Analysi'!H51:H53)) -> 0.20209998 | I21: =('Financial Statment Analysi'!I20-'Financial Statment Analysi'!I26)/(SUM('Financial Statment Analysi'!I51:I53)) -> 0.18355825 | K21: =IFERROR(AVERAGE(D21:I21),0) -> 0.16714055 | L21: =IFERROR(MEDIAN(D21:I21),0) -> 0.17982225
B22: Retained Earnings % | D22: =IFERROR('Financial Statment Analysi'!D46,0) -> 0.72809198 | E22: =IFERROR('Financial Statment Analysi'!E46,0) -> 0.46259904 | F22: =IFERROR('Financial Statment Analysi'!F46,0) -> 0.51383208 | G22: =IFERROR('Financial Statment Analysi'!G46,0) -> 0.49548808 | H22: =IFERROR('Financial Statment Analysi'!H46,0) -> 0.4369163 | I22: =IFERROR('Financial Statment Analysi'!I46,0) -> 0.29955807 | K22: =IFERROR(AVERAGE(D22:I22),0) -> 0.48941426 | L22: =IFERROR(MEDIAN(D22:I22),0) -> 0.47904356
B23: Return on Equity | D23: =IFERROR('Financial Statment Analysi'!D35/SUM('Financial Statment Analysi'!D51:D52),0) -> 0.12574179 | E23: =IFERROR('Financial Statment Analysi'!E35/SUM('Financial Statment Analysi'!E51:E52),0) -> 0.075585238 | F23: =IFERROR('Financial Statment Analysi'!F35/SUM('Financial Statment Analysi'!F51:F52),0) -> 0.09366672 | G23: =IFERROR('Financial Statment Analysi'!G35/SUM('Financial Statment Analysi'!G51:G52),0) -> 0.13380671 | H23: =IFERROR('Financial Statment Analysi'!H35/SUM('Financial Statment Analysi'!H51:H52),0) -> 0.13742351 | I23: =IFERROR('Financial Statment Analysi'!I35/SUM('Financial Statment Analysi'!I51:I52),0) -> 0.12867238 | K23: =IFERROR(AVERAGE(D23:I23),0) -> 0.11581606 | L23: =IFERROR(MEDIAN(D23:I23),0) -> 0.12720708
B24: Self Sustained Growth Rate | D24: =IFERROR(D23*D22,0) -> 0.091551589 | E24: =IFERROR(E23*E22,0) -> 0.034965659 | F24: =IFERROR(F23*F22,0) -> 0.048128966 | G24: =IFERROR(G23*G22,0) -> 0.066299629 | H24: =IFERROR(H23*H22,0) -> 0.06004257 | I24: =IFERROR(I23*I22,0) -> 0.038544849 | K24: =IFERROR(AVERAGE(D24:I24),0) -> 0.056588877 | L24: =IFERROR(MEDIAN(D24:I24),0) -> 0.054085768
B25: Interest Coverage Ratio | D25: =('Financial Statment Analysi'!D20-'Financial Statment Analysi'!D26)/'Financial Statment Analysi'!D23 -> 95.410487 | E25: =('Financial Statment Analysi'!E20-'Financial Statment Analysi'!E26)/'Financial Statment Analysi'!E23 -> 81.00304 | F25: =('Financial Statment Analysi'!F20-'Financial Statment Analysi'!F26)/'Financial Statment Analysi'!F23 -> 91.887114 | G25: =('Financial Statment Analysi'!G20-'Financial Statment Analysi'!G26)/'Financial Statment Analysi'!G23 -> 104.19379 | H25: =('Financial Statment Analysi'!H20-'Financial Statment Analysi'!H26)/'Financial Statment Analysi'!H23 -> 73.344536 | I25: =('Financial Statment Analysi'!I20-'Financial Statment Analysi'!I26)/'Financial Statment Analysi'!I23 -> 73.486198 | K25: =IFERROR(AVERAGE(D25:I25),0) -> 86.554194 | L25: =IFERROR(MEDIAN(D25:I25),0) -> 86.445077
B27: Debtor Turnover Ratio | D27: =IFERROR('Financial Statment Analysi'!D8/'Financial Statment Analysi'!D63,0) -> 105.50461 | E27: =IFERROR('Financial Statment Analysi'!E8/'Financial Statment Analysi'!E63,0) -> 55.136254 | F27: =IFERROR('Financial Statment Analysi'!F8/'Financial Statment Analysi'!F63,0) -> 34.094259 | G27: =IFERROR('Financial Statment Analysi'!G8/'Financial Statment Analysi'!G63,0) -> 39.147186 | H27: =IFERROR('Financial Statment Analysi'!H8/'Financial Statment Analysi'!H63,0) -> 44.239339 | I27: =IFERROR('Financial Statment Analysi'!I8/'Financial Statment Analysi'!I63,0) -> 34.332199 | K27: =IFERROR(AVERAGE(D27:I27),0) -> 52.075641 | L27: =IFERROR(MEDIAN(D27:I27),0) -> 41.693263
B28: Creditor Turnover Ratio | D28: =IFERROR('Financial Statment Analysi'!D8/'Financial Statment Analysi'!D54,0) -> 4.1236243 | E28: =IFERROR('Financial Statment Analysi'!E8/'Financial Statment Analysi'!E54,0) -> 3.0056906 | F28: =IFERROR('Financial Statment Analysi'!F8/'Financial Statment Analysi'!F54,0) -> 3.0074384 | G28: =IFERROR('Financial Statment Analysi'!G8/'Financial Statment Analysi'!G54,0) -> 3.6852167 | H28: =IFERROR('Financial Statment Analysi'!H8/'Financial Statment Analysi'!H54,0) -> 3.5559594 | I28: =IFERROR('Financial Statment Analysi'!I8/'Financial Statment Analysi'!I54,0) -> 3.4817493 | K28: =IFERROR(AVERAGE(D28:I28),0) -> 3.4766131 | L28: =IFERROR(MEDIAN(D28:I28),0) -> 3.5188543
B29: Inventory Turnover Ratio | D29: =IFERROR('Financial Statment Analysi'!D8/'Financial Statment Analysi'!D64,0) -> 15.992976 | E29: =IFERROR('Financial Statment Analysi'!E8/'Financial Statment Analysi'!E64,0) -> 9.9706723 | F29: =IFERROR('Financial Statment Analysi'!F8/'Financial Statment Analysi'!F64,0) -> 9.0938096 | G29: =IFERROR('Financial Statment Analysi'!G8/'Financial Statment Analysi'!G64,0) -> 11.296721 | H29: =IFERROR('Financial Statment Analysi'!H8/'Financial Statment Analysi'!H64,0) -> 11.730499 | I29: =IFERROR('Financial Statment Analysi'!I8/'Financial Statment Analysi'!I64,0) -> 12.06737 | K29: =IFERROR(AVERAGE(D29:I29),0) -> 11.692008 | L29: =IFERROR(MEDIAN(D29:I29),0) -> 11.51361
B30: Fixed Capital Turnover Ratio | D30: =IFERROR('Financial Statment Analysi'!D8/'Financial Statment Analysi'!D57,0) -> 3.8500538 | E30: =IFERROR('Financial Statment Analysi'!E8/'Financial Statment Analysi'!E57,0) -> 3.5837546 | F30: =IFERROR('Financial Statment Analysi'!F8/'Financial Statment Analysi'!F57,0) -> 4.247789 | G30: =IFERROR('Financial Statment Analysi'!G8/'Financial Statment Analysi'!G57,0) -> 5.3688601 | H30: =IFERROR('Financial Statment Analysi'!H8/'Financial Statment Analysi'!H57,0) -> 5.6738586 | I30: =IFERROR('Financial Statment Analysi'!I8/'Financial Statment Analysi'!I57,0) -> 5.4327085 | K30: =IFERROR(AVERAGE(D30:I30),0) -> 4.6928374 | L30: =IFERROR(MEDIAN(D30:I30),0) -> 4.8083246
B31: Capital Turnover Ratio | D31: =IFERROR('Financial Statment Analysi'!D8/SUM('Financial Statment Analysi'!D51:D52),0) -> 0.91710692 | E31: =IFERROR('Financial Statment Analysi'!E8/SUM('Financial Statment Analysi'!E51:E52),0) -> 0.76239631 | F31: =IFERROR('Financial Statment Analysi'!F8/SUM('Financial Statment Analysi'!F51:F52),0) -> 0.81676951 | G31: =IFERROR('Financial Statment Analysi'!G8/SUM('Financial Statment Analysi'!G51:G52),0) -> 0.96343631 | H31: =IFERROR('Financial Statment Analysi'!H8/SUM('Financial Statment Analysi'!H51:H52),0) -> 0.91633662 | I31: =IFERROR('Financial Statment Analysi'!I8/SUM('Financial Statment Analysi'!I51:I52),0) -> 0.88607794 | K31: =IFERROR(AVERAGE(D31:I31),0) -> 0.8770206 | L31: =IFERROR(MEDIAN(D31:I31),0) -> 0.90120728
B33: (in days)
B34: Debtors Days | D34: =IFERROR(365/D27,0) -> 3.4595645 | E34: =IFERROR(365/E27,0) -> 6.6199636 | F34: =IFERROR(365/F27,0) -> 10.705615 | G34: =IFERROR(365/G27,0) -> 9.3237863 | H34: =IFERROR(365/H27,0) -> 8.2505754 | I34: =IFERROR(365/I27,0) -> 10.631419 | K34: =IFERROR(AVERAGE(D34:I34),0) -> 8.1651539 | L34: =IFERROR(MEDIAN(D34:I34),0) -> 8.7871809
B35: Payable Days | D35: =IFERROR(365/D28,0) -> 88.514368 | E35: =IFERROR(365/E28,0) -> 121.43632 | F35: =IFERROR(365/F28,0) -> 121.36574 | G35: =IFERROR(365/G28,0) -> 99.044379 | H35: =IFERROR(365/H28,0) -> 102.64459 | I35: =IFERROR(365/I28,0) -> 104.83236 | K35: =IFERROR(AVERAGE(D35:I35),0) -> 106.30629 | L35: =IFERROR(MEDIAN(D35:I35),0) -> 103.73848
B36: Inventory Days | D36: =IFERROR(365/D29,0) -> 22.822519 | E36: =IFERROR(365/E29,0) -> 36.607361 | F36: =IFERROR(365/F29,0) -> 40.137194 | G36: =IFERROR(365/G29,0) -> 32.310261 | H36: =IFERROR(365/H29,0) -> 31.115472 | I36: =IFERROR(365/I29,0) -> 30.246856 | K36: =IFERROR(AVERAGE(D36:I36),0) -> 32.20661 | L36: =IFERROR(MEDIAN(D36:I36),0) -> 31.712866
B37: Cash Conevrsion Cycle | D37: =IFERROR(SUM(D34,D36)-D35,0) -> -62.232285 | E37: =IFERROR(SUM(E34,E36)-E35,0) -> -78.208994 | F37: =IFERROR(SUM(F34,F36)-F35,0) -> -70.522935 | G37: =IFERROR(SUM(G34,G36)-G35,0) -> -57.410332 | H37: =IFERROR(SUM(H34,H36)-H35,0) -> -63.278545 | I37: =IFERROR(SUM(I34,I36)-I35,0) -> -63.954087 | K37: =IFERROR(AVERAGE(D37:I37),0) -> -65.93453 | L37: =IFERROR(MEDIAN(D37:I37),0) -> -63.616316
B40: CFO/Sales | D40: =IFERROR('Financial Statment Analysi'!D75/'Financial Statment Analysi'!D8,0) -> 0.18507731 | E40: =IFERROR('Financial Statment Analysi'!E75/'Financial Statment Analysi'!E8,0) -> 0.19391079 | F40: =IFERROR('Financial Statment Analysi'!F75/'Financial Statment Analysi'!F8,0) -> 0.14828755 | G40: =IFERROR('Financial Statment Analysi'!G75/'Financial Statment Analysi'!G8,0) -> 0.19544556 | H40: =IFERROR('Financial Statment Analysi'!H75/'Financial Statment Analysi'!H8,0) -> 0.22519107 | I40: =IFERROR('Financial Statment Analysi'!I75/'Financial Statment Analysi'!I8,0) -> 0.21090865 | K40: =IFERROR(AVERAGE(D40:I40),0) -> 0.19313682 | L40: =IFERROR(MEDIAN(D40:I40),0) -> 0.19467818
B41: CFO/Total Assets | D41: =IFERROR('Financial Statment Analysi'!D75/'Financial Statment Analysi'!D68,0) -> 0.13607696 | E41: =IFERROR('Financial Statment Analysi'!E75/'Financial Statment Analysi'!E68,0) -> 0.11614914 | F41: =IFERROR('Financial Statment Analysi'!F75/'Financial Statment Analysi'!F68,0) -> 0.09461314 | G41: =IFERROR('Financial Statment Analysi'!G75/'Financial Statment Analysi'!G68,0) -> 0.14703161 | H41: =IFERROR('Financial Statment Analysi'!H75/'Financial Statment Analysi'!H68,0) -> 0.16109405 | I41: =IFERROR('Financial Statment Analysi'!I75/'Financial Statment Analysi'!I68,0) -> 0.14645838 | K41: =IFERROR(AVERAGE(D41:I41),0) -> 0.13357055 | L41: =IFERROR(MEDIAN(D41:I41),0) -> 0.14126767
B42: CFO/Total Debt | D42: =IFERROR('Financial Statment Analysi'!D75/'Financial Statment Analysi'!D53,0) -> 6.8036948 | E42: =IFERROR('Financial Statment Analysi'!E75/'Financial Statment Analysi'!E53,0) -> 7.71252 | F42: =IFERROR('Financial Statment Analysi'!F75/'Financial Statment Analysi'!F53,0) -> 14.177328 | G42: =IFERROR('Financial Statment Analysi'!G75/'Financial Statment Analysi'!G53,0) -> 9.7869699 | H42: =IFERROR('Financial Statment Analysi'!H75/'Financial Statment Analysi'!H53,0) -> 8.8778133 | I42: =IFERROR('Financial Statment Analysi'!I75/'Financial Statment Analysi'!I53,0) -> 8.6873158 | K42: =IFERROR(AVERAGE(D42:I42),0) -> 9.3409403 | L42: =IFERROR(MEDIAN(D42:I42),0) -> 8.7825646

Sheet Financial Statment Analysi
B4: ="Historical Financial Statement - "&'Data Sheet'!B1 -> Historical Financial Statement - EICHER MOTORS LTD
B5: Years | D5: ='Data Sheet'!F16 -> 43921 | E5: ='Data Sheet'!G16 -> 44286 | F5: ='Data Sheet'!H16 -> 44651 | G5: ='Data Sheet'!I16 -> 45016 | H5: ='Data Sheet'!J16 -> 45382 | I5: ='Data Sheet'!K16 -> 45747 | J5: LTM
A7: # | B7: Income Statement
B8: Sales | D8: =IFERROR('Data Sheet'!F17,0) -> 9153.58 | E8: =IFERROR('Data Sheet'!G17,0) -> 8720.35 | F8: =IFERROR('Data Sheet'!H17,0) -> 10297.83 | G8: =IFERROR('Data Sheet'!I17,0) -> 14442.18 | H8: =IFERROR('Data Sheet'!J17,0) -> 16535.78 | I8: =IFERROR('Data Sheet'!K17,0) -> 18870.35 | J8: =IFERROR(SUM('Data Sheet'!H42:K42),0) -> 22568.58
B9: Sales Growth | D9: - | E9: =IFERROR(E8/D8-1,0) -> -0.047329023 | F9: =IFERROR(F8/E8-1,0) -> 0.18089641 | G9: =IFERROR(G8/F8-1,0) -> 0.40244887 | H9: =IFERROR(H8/G8-1,0) -> 0.14496426 | I9: =IFERROR(I8/H8-1,0) -> 0.14118294 | J9: =IFERROR(J8/I8-1,0) -> 0.195981
B11: COGS | D11: =IFERROR(SUM('Data Sheet'!F18,'Data Sheet'!F20:F22)-1*'Data Sheet'!F19,0) -> 6113.89 | E11: =IFERROR(SUM('Data Sheet'!G18,'Data Sheet'!G20:G22)-1*'Data Sheet'!G19,0) -> 6261.01 | F11: =IFERROR(SUM('Data Sheet'!H18,'Data Sheet'!H20:H22)-1*'Data Sheet'!H19,0) -> 7167.9 | G11: =IFERROR(SUM('Data Sheet'!I18,'Data Sheet'!I20:I22)-1*'Data Sheet'!I19,0) -> 9689.9 | H11: =IFERROR(SUM('Data Sheet'!J18,'Data Sheet'!J20:J22)-1*'Data Sheet'!J19,0) -> 10700.98 | I11: =IFERROR(SUM('Data Sheet'!K18,'Data Sheet'!K20:K22)-1*'Data Sheet'!K19,0) -> 12241.11 | J11: =IFERROR(SUM('Data Sheet'!H43:K43),0) -> 17039.49
B12: COGS % Sales | D12: =D11/D8 -> 0.66792337 | E12: =E11/E8 -> 0.71797692 | F12: =F11/F8 -> 0.69605927 | G12: =G11/G8 -> 0.67094441 | H12: =H11/H8 -> 0.64714093 | I12: =I11/I8 -> 0.64869544 | J12: =J11/J8 -> 0.7550094
B14: Gross Profit | D14: =D8-D11 -> 3039.69 | E14: =E8-E11 -> 2459.34 | F14: =F8-F11 -> 3129.93 | G14: =G8-G11 -> 4752.28 | H14: =H8-H11 -> 5834.8 | I14: =I8-I11 -> 6629.24 | J14: =J8-J11 -> 5529.09
B15: Gross Margins | D15: =D14/D8 -> 0.33207663 | E15: =E14/E8 -> 0.28202308 | F15: =F14/F8 -> 0.30394073 | G15: =G14/G8 -> 0.32905559 | H15: =H14/H8 -> 0.35285907 | I15: =I14/I8 -> 0.35130456 | J15: =J14/J8 -> 0.2449906
B17: Selling & General Expenses | D17: =IFERROR(SUM('Data Sheet'!F23:F24),0) -> 856.8 | E17: =IFERROR(SUM('Data Sheet'!G23:G24),0) -> 676.11 | F17: =IFERROR(SUM('Data Sheet'!H23:H24),0) -> 952.36 | G17: =IFERROR(SUM('Data Sheet'!I23:I24),0) -> 1306.56 | H17: =IFERROR(SUM('Data Sheet'!J23:J24),0) -> 1505.43 | I17: =IFERROR(SUM('Data Sheet'!K23:K24),0) -> 1906.67 | J17: =IFERROR(SUM('Data Sheet'!L23:L24),0) -> 0
B18: S & G Exp % Sales | D18: =D17/D8 -> 0.093602722 | E18: =E17/E8 -> 0.077532438 | F18: =F17/F8 -> 0.09248162 | G18: =G17/G8 -> 0.090468336 | H18: =H17/H8 -> 0.091040761 | I18: =I17/I8 -> 0.10104052 | J18: =J17/J8 -> 0
B20: EBITDA | D20: =D14-D17 -> 2182.89 | E20: =E14-E17 -> 1783.23 | F20: =F14-F17 -> 2177.57 | G20: =G14-G17 -> 3445.72 | H20: =H14-H17 -> 4329.37 | I20: =I14-I17 -> 4722.57 | J20: =J14-J17 -> 5529.09
B21: EBITDA % Sales | D21: =D20/D8 -> 0.23847391 | E21: =E20/E8 -> 0.20449065 | F21: =F20/F8 -> 0.21145911 | G21: =G20/G8 -> 0.23858725 | H21: =H20/H8 -> 0.26181831 | I21: =I20/I8 -> 0.25026404 | J21: =J20/J8 -> 0.2449906
B23: Interest | D23: =IFERROR('Data Sheet'!F27,0) -> 18.88 | E23: =IFERROR('Data Sheet'!G27,0) -> 16.45 | F23: =IFERROR('Data Sheet'!H27,0) -> 18.78 | G23: =IFERROR('Data Sheet'!I27,0) -> 28.02 | H23: =IFERROR('Data Sheet'!J27,0) -> 50.88 | I23: =IFERROR('Data Sheet'!K27,0) -> 54.34 | J23: =IFERROR(SUM('Data Sheet'!H46:K46),0) -> 66.87
B24: Interest % Sales | D24: =D23/D8 -> 0.002062581 | E24: =E23/E8 -> 0.0018863922 | F24: =F23/F8 -> 0.0018236852 | G24: =G23/G8 -> 0.0019401503 | H24: =H23/H8 -> 0.003076964 | I24: =I23/I8 -> 0.0028796498 | J24: =J23/J8 -> 0.0029629689
B26: Depreciation | D26: =IFERROR('Data Sheet'!F26,0) -> 381.54 | E26: =IFERROR('Data Sheet'!G26,0) -> 450.73 | F26: =IFERROR('Data Sheet'!H26,0) -> 451.93 | G26: =IFERROR('Data Sheet'!I26,0) -> 526.21 | H26: =IFERROR('Data Sheet'!J26,0) -> 597.6 | I26: =IFERROR('Data Sheet'!K26,0) -> 729.33 | J26: =IFERROR(SUM('Data Sheet'!H45:K45),0) -> 810.09
B27: Depreciation % Sales | D27: =D26/D8 -> 0.041682052 | E27: =E26/E8 -> 0.051687146 | F27: =F26/F8 -> 0.043885945 | G27: =G26/G8 -> 0.036435635 | H27: =H26/H8 -> 0.036139813 | I27: =I26/I8 -> 0.038649522 | J27: =J26/J8 -> 0.035894593
B29: Earnings Before Tax | D29: =IFERROR(D20-SUM(D23,D26),0) -> 1782.47 | E29: =IFERROR(E20-SUM(E23,E26),0) -> 1316.05 | F29: =IFERROR(F20-SUM(F23,F26),0) -> 1706.86 | G29: =IFERROR(G20-SUM(G23,G26),0) -> 2891.49 | H29: =IFERROR(H20-SUM(H23,H26),0) -> 3680.89 | I29: =IFERROR(I20-SUM(I23,I26),0) -> 3938.9 | J29: =IFERROR(J20-SUM(J23,J26),0) -> 4652.13
B30: EBT % Sales | D30: =D29/D8 -> 0.19472928 | E30: =E29/E8 -> 0.15091711 | F30: =F29/F8 -> 0.16574948 | G30: =G29/G8 -> 0.20021146 | H30: =H29/H8 -> 0.22260153 | I30: =I29/I8 -> 0.20873487 | J30: =J29/J8 -> 0.20613304
B32: Tax | D32: =IFERROR('Data Sheet'!F29,0) -> 527.45 | E32: =IFERROR('Data Sheet'!G29,0) -> 451.5 | F32: =IFERROR('Data Sheet'!H29,0) -> 525.91 | G32: =IFERROR('Data Sheet'!I29,0) -> 885.69 | H32: =IFERROR('Data Sheet'!J29,0) -> 1201.01 | I32: =IFERROR('Data Sheet'!K29,0) -> 1198.63 | J32: =IFERROR(SUM('Data Sheet'!H48:K48),0) -> 1476.93
B33: Effective Tax Rate | D33: =D32/D29 -> 0.29590961 | E33: =E32/E29 -> 0.34307207 | F33: =F32/F29 -> 0.30811549 | G33: =G32/G29 -> 0.3063092 | H33: =H32/H29 -> 0.3262825 | I33: =I32/I29 -> 0.30430577 | J33: =J32/J29 -> 0.31747393
B35: Net Profit | D35: =IFERROR(D29-D32,0) -> 1255.02 | E35: =IFERROR(E29-E32,0) -> 864.55 | F35: =IFERROR(F29-F32,0) -> 1180.95 | G35: =IFERROR(G29-G32,0) -> 2005.8 | H35: =IFERROR(H29-H32,0) -> 2479.88 | I35: =IFERROR(I29-I32,0) -> 2740.27 | J35: =IFERROR(J29-J32,0) -> 3175.2
B36: Net Margins | D36: =D35/D8 -> 0.13710701 | E36: =E35/E8 -> 0.099141663 | F36: =F35/F8 -> 0.1146795 | G36: =G35/G8 -> 0.13888485 | H36: =H35/H8 -> 0.14997055 | I36: =I35/I8 -> 0.14521564 | J36: =J35/J8 -> 0.14069117
B38: No of Equity Shares | D38: =IFERROR('Data Sheet'!F93,0) -> 27.31 | E38: =IFERROR('Data Sheet'!G93,0) -> 27.33 | F38: =IFERROR('Data Sheet'!H93,0) -> 27.34 | G38: =IFERROR('Data Sheet'!I93,0) -> 27.35 | H38: =IFERROR('Data Sheet'!J93,0) -> 27.38 | I38: =IFERROR('Data Sheet'!K93,0) -> 27.42 | J38: =I38 -> 27.42
B40: Earnings Per Share | D40: =IFERROR(D35/D38,0) -> 45.954595 | E40: =IFERROR(E35/E38,0) -> 31.633736 | F40: =IFERROR(F35/F38,0) -> 43.194952 | G40: =IFERROR(G35/G38,0) -> 73.338208 | H40: =IFERROR(H35/H38,0) -> 90.572681 | I40: =IFERROR(I35/I38,0) -> 99.936907 | J40: =IFERROR(J35/J38,0) -> 115.79869
B41: EPS Growth | E41: =E40/D40-1 -> -0.31163063 | F41: =F40/E40-1 -> 0.36547111 | G41: =G40/F40-1 -> 0.69784209 | H41: =H40/G40-1 -> 0.23499991 | I41: =I40/H40-1 -> 0.10338908 | J41: =J40/I40-1 -> 0.15871794
B43: Dividend Per Share | D43: =IFERROR('Data Sheet'!F31/'Financial Statment Analysi'!D38,0) -> 12.495423 | E43: =IFERROR('Data Sheet'!G31/'Financial Statment Analysi'!E38,0) -> 17 | F43: =IFERROR('Data Sheet'!H31/'Financial Statment Analysi'!F38,0) -> 21 | G43: =IFERROR('Data Sheet'!I31/'Financial Statment Analysi'!G38,0) -> 37 | H43: =IFERROR('Data Sheet'!J31/'Financial Statment Analysi'!H38,0) -> 51 | I43: =IFERROR('Data Sheet'!K31/'Financial Statment Analysi'!I38,0) -> 70 | J43: =IFERROR('Data Sheet'!L31/'Financial Statment Analysi'!J38,0) -> 0
B44: Dividend Payout Ratio | D44: =IFERROR(D43/D40,0) -> 0.27190802 | E44: =IFERROR(E43/E40,0) -> 0.53740096 | F44: =IFERROR(F43/F40,0) -> 0.48616792 | G44: =IFERROR(G43/G40,0) -> 0.50451192 | H44: =IFERROR(H43/H40,0) -> 0.5630837 | I44: =IFERROR(I43/I40,0) -> 0.70044193 | J44: =IFERROR(J43/J40,0) -> 0
B46: Retained Earnings | D46: =IFERROR(IF(D40>D43,1-D44),0) -> 0.72809198 | E46: =IFERROR(IF(E40>E43,1-E44),0) -> 0.46259904 | F46: =IFERROR(IF(F40>F43,1-F44),0) -> 0.51383208 | G46: =IFERROR(IF(G40>G43,1-G44),0) -> 0.49548808 | H46: =IFERROR(IF(H40>H43,1-H44),0) -> 0.4369163 | I46: =IFERROR(IF(I40>I43,1-I44),0) -> 0.29955807 | J46: =IFERROR(IF(J40>J43,1-J44),0) -> 1
A50: # | B50: Balance Sheet
B51: Equity Share Capital | D51: =IFERROR('Data Sheet'!F57,0) -> 27.3 | E51: =IFERROR('Data Sheet'!G57,0) -> 27.33 | F51: =IFERROR('Data Sheet'!H57,0) -> 27.34 | G51: =IFERROR('Data Sheet'!I57,0) -> 27.35 | H51: =IFERROR('Data Sheet'!J57,0) -> 27.38 | I51: =IFERROR('Data Sheet'!K57,0) -> 27.42
B52: Reserves | D52: =IFERROR('Data Sheet'!F58,0) -> 9953.63 | E52: =IFERROR('Data Sheet'!G58,0) -> 11410.75 | F52: =IFERROR('Data Sheet'!H58,0) -> 12580.66 | G52: =IFERROR('Data Sheet'!I58,0) -> 14962.93 | H52: =IFERROR('Data Sheet'!J58,0) -> 18018.15 | I52: =IFERROR('Data Sheet'!K58,0) -> 21269.07
B53: Borrowings | D53: =IFERROR('Data Sheet'!F59,0) -> 249 | E53: =IFERROR('Data Sheet'!G59,0) -> 219.25 | F53: =IFERROR('Data Sheet'!H59,0) -> 107.71 | G53: =IFERROR('Data Sheet'!I59,0) -> 288.41 | H53: =IFERROR('Data Sheet'!J59,0) -> 419.44 | I53: =IFERROR('Data Sheet'!K59,0) -> 458.13
B54: Other Liabilities | D54: =IFERROR('Data Sheet'!F60,0) -> 2219.79 | E54: =IFERROR('Data Sheet'!G60,0) -> 2901.28 | F54: =IFERROR('Data Sheet'!H60,0) -> 3424.12 | G54: =IFERROR('Data Sheet'!I60,0) -> 3918.95 | H54: =IFERROR('Data Sheet'!J60,0) -> 4650.16 | I54: =IFERROR('Data Sheet'!K60,0) -> 5419.79
B55: Total Liabilities | D55: =IFERROR('Data Sheet'!F61,0) -> 12449.72 | E55: =IFERROR('Data Sheet'!G61,0) -> 14558.61 | F55: =IFERROR('Data Sheet'!H61,0) -> 16139.83 | G55: =IFERROR('Data Sheet'!I61,0) -> 19197.64 | H55: =IFERROR('Data Sheet'!J61,0) -> 23115.13 | I55: =IFERROR('Data Sheet'!K61,0) -> 27174.41
B57: Fixed Assets Net Block | D57: =IFERROR('Data Sheet'!F62,0) -> 2377.52 | E57: =IFERROR('Data Sheet'!G62,0) -> 2433.3 | F57: =IFERROR('Data Sheet'!H62,0) -> 2424.28 | G57: =IFERROR('Data Sheet'!I62,0) -> 2689.99 | H57: =IFERROR('Data Sheet'!J62,0) -> 2914.38 | I57: =IFERROR('Data Sheet'!K62,0) -> 3473.47
B58: Capital Work in Progress | D58: =IFERROR('Data Sheet'!F63,0) -> 312.17 | E58: =IFERROR('Data Sheet'!G63,0) -> 314.29 | F58: =IFERROR('Data Sheet'!H63,0) -> 504.78 | G58: =IFERROR('Data Sheet'!I63,0) -> 472.07 | H58: =IFERROR('Data Sheet'!J63,0) -> 555.1 | I58: =IFERROR('Data Sheet'!K63,0) -> 491.47
B59: Investments | D59: =IFERROR('Data Sheet'!F64,0) -> 5748.77 | E59: =IFERROR('Data Sheet'!G64,0) -> 3902.14 | F59: =IFERROR('Data Sheet'!H64,0) -> 7720.58 | G59: =IFERROR('Data Sheet'!I64,0) -> 12320.66 | H59: =IFERROR('Data Sheet'!J64,0) -> 13526.96 | I59: =IFERROR('Data Sheet'!K64,0) -> 14790.9
B60: Other Assets | D60: =IFERROR('Data Sheet'!F65-SUM('Data Sheet'!F67:F69),0) -> 401.56 | E60: =IFERROR('Data Sheet'!G65-SUM('Data Sheet'!G67:G69),0) -> 1045.76 | F60: =IFERROR('Data Sheet'!H65-SUM('Data Sheet'!H67:H69),0) -> 1333.28 | G60: =IFERROR('Data Sheet'!I65-SUM('Data Sheet'!I67:I69),0) -> 1301.98 | H60: =IFERROR('Data Sheet'!J65-SUM('Data Sheet'!J67:J69),0) -> 4188.96 | I60: =IFERROR('Data Sheet'!K65-SUM('Data Sheet'!K67:K69),0) -> 6042.17
B61: Total Non Current Assets | D61: =IFERROR(SUM(D57:D60),0) -> 8840.02 | E61: =IFERROR(SUM(E57:E60),0) -> 7695.49 | F61: =IFERROR(SUM(F57:F60),0) -> 11982.92 | G61: =IFERROR(SUM(G57:G60),0) -> 16784.7 | H61: =IFERROR(SUM(H57:H60),0) -> 21185.4 | I61: =IFERROR(SUM(I57:I60),0) -> 24798.01
...

Sheet Data Sheet
A1: COMPANY NAME | B1: EICHER MOTORS LTD | E1: =IF(B2<>B3, "A NEW VERSION OF THE WORKSHEET IS AVAILABLE", "")
A2: LATEST VERSION | B2: 2.1 | E2: PLEASE DO NOT MAKE ANY CHANGES TO THIS SHEET
A3: CURRENT VERSION | B3: 2.1
A5: META
A6: Number of shares | B6: =IF(B9>0, B9/B8, 0) -> 27.431419
A7: Face Value | B7: 1
A8: Current Price | B8: 8042.8
A9: Market Capitalization | B9: 220625.42
A15: PROFIT & LOSS
A16: Report Date | B16: 42460 | C16: 42825 | D16: 43190 | E16: 43555 | F16: 43921 | G16: 44286 | H16: 44651 | I16: 45016 | J16: 45382 | K16: 45747
A17: Sales | B17: 6173.46 | C17: 7033.36 | D17: 8964.96 | E17: 9797.06 | F17: 9153.58 | G17: 8720.35 | H17: 10297.83 | I17: 14442.18 | J17: 16535.78 | K17: 18870.35
A18: Raw Material Cost | B18: 3497.73 | C18: 3725.72 | D18: 4679.07 | E18: 5269.64 | F18: 4914.58 | G18: 5319.85 | H18: 6107.28 | I18: 8281.04 | J18: 9187.35 | K18: 10470.09
A19: Change in Inventory | B19: 62.05 | C19: 19.61 | D19: 33.87 | E19: 210.16 | F19: -84.09 | G19: 205.9 | H19: 148.59 | I19: 63.25 | J19: 197.03 | K19: 163.51
A20: Power and Fuel | B20: 46.18 | C20: 46.02 | D20: 52.41 | E20: 66.96 | F20: 62.86 | G20: 52.98 | H20: 55.78 | I20: 72.97 | J20: 80.61 | K20: 89.53
A21: Other Mfr. Exp | B21: 173.76 | C21: 173.09 | D21: 210.76 | E21: 263.49 | F21: 256.58 | G21: 250.85 | H21: 332.41 | I21: 397.21 | J21: 394.36 | K21: 453.77
A22: Employee Cost | B22: 350.21 | C22: 426.28 | D22: 573.68 | E22: 702.44 | F22: 795.78 | G22: 843.23 | H22: 821.02 | I22: 1001.93 | J22: 1235.69 | K22: 1391.23
A23: Selling and admin | B23: 397.4 | C23: 412.25 | D23: 565.66 | E23: 654.82 | F23: 667.16 | G23: 522.52 | H23: 815.51 | I23: 1164.58 | J23: 1293.02 | K23: 1669.63
A24: Other Expenses | B24: 80.5 | C24: 95.3 | D24: 108.62 | E24: 145.63 | F24: 189.64 | G24: 153.59 | H24: 136.85 | I24: 141.98 | J24: 212.41 | K24: 237.04
A25: Other Income | B25: 325.91 | C25: 416.44 | D25: 535.66 | E25: 700.66 | F25: 572.42 | G25: 482.34 | H25: 495.65 | I25: 908.14 | J25: 1521.13 | K25: 1994.17
A26: Depreciation | B26: 136.6 | C26: 153.81 | D26: 223.3 | E26: 300.28 | F26: 381.54 | G26: 450.73 | H26: 451.93 | I26: 526.21 | J26: 597.6 | K26: 729.33
A27: Interest | B27: 2.12 | C27: 3.56 | D27: 5.34 | E27: 7.33 | F27: 18.88 | G27: 16.45 | H27: 18.78 | I27: 28.02 | J27: 50.88 | K27: 54.34
... A31: Dividend Amount | B31: 271.6 | C31: 272.1 | D31: 299.86 | E31: 341 | F31: 341.25 | G31: 464.61 | H31: 574.14 | I31: 1011.95 | J31: 1396.38 | K31: 1919.4
A40: Quarters
A41: Report Date | B41: 45199 | C41: 45291 | D41: 45382 | E41: 45473 | F41: 45565 | G41: 45657 | H41: 45747 | I41: 45838 | J41: 45930 | K41: 46022
A42: Sales | B42: 4114.53 | C42: 4178.84 | D42: 4256.04 | E42: 4393.05 | F42: 4263.07 | G42: 4973.12 | H42: 5241.11 | I42: 5041.84 | J42: 6171.59 | K42: 6114.04
A43: Expenses | B43: 3027.37 | C43: 3088.57 | D43: 3127.4 | E43: 3227.62 | F43: 3175.35 | G43: 3771.93 | H43: 3983.42 | I43: 3839.06 | J43: 4659.69 | K43: 4557.32
A44: Other Income | B44: 375.4 | C44: 367.58 | D44: 436.96 | E44: 456.51 | F44: 467.53 | G44: 452.29 | H44: 628.38 | I44: 603.17 | J44: 485.83 | K44: 464.85
A45: Depreciation | B45: 142.54 | C45: 147.54 | D45: 165.25 | E45: 168.63 | F45: 180.06 | G45: 179.27 | H45: 201.37 | I45: 198.06 | J45: 199.56 | K45: 211.1
A46: Interest | B46: 12.68 | C46: 12.43 | D46: 15.34 | E46: 12.27 | F46: 13.14 | G46: 13.39 | H46: 15.54 | I46: 14.9 | J46: 19.16 | K46: 17.27
A47: Profit before tax | B47: 1307.34 | C47: 1297.88 | D47: 1385.01 | E47: 1441.04 | F47: 1362.05 | G47: 1460.82 | H47: 1669.16 | I47: 1592.99 | J47: 1779.01 | K47: 1793.2
A48: Tax | B48: 291.09 | C48: 301.91 | D48: 314.56 | E48: 339.58 | F48: 261.72 | G48: 290.32 | H48: 307.01 | I48: 387.77 | J48: 409.56 | K48: 372.59
A49: Net profit | B49: 1016.25 | C49: 995.97 | D49: 1070.45 | E49: 1101.46 | F49: 1100.33 | G49: 1170.5 | H49: 1362.15 | I49: 1205.22 | J49: 1369.45 | K49: 1420.61
A50: Operating Profit | B50: 1087.16 | C50: 1090.27 | D50: 1128.64 | E50: 1165.43 | F50: 1087.72 | G50: 1201.19 | H50: 1257.69 | I50: 1202.78 | J50: 1511.9 | K50: 1556.72
A55: BALANCE SHEET
A56: Report Date | B56: 42460 | C56: 42825 | D56: 43190 | E56: 43555 | F56: 43921 | G56: 44286 | H56: 44651 | I56: 45016 | J56: 45382 | K56: 45747
A57: Equity Share Capital | B57: 27.16 | C57: 27.21 | D57: 27.26 | E57: 27.28 | F57: 27.3 | G57: 27.33 | H57: 27.34 | I57: 27.35 | J57: 27.38 | K57: 27.42
A58: Reserves | B58: 3625.93 | C58: 5317.86 | D58: 7002.81 | E58: 8891.44 | F58: 9953.63 | G58: 11410.75 | H58: 12580.66 | I58: 14962.93 | J58: 18018.15 | K58: 21269.07
A59: Borrowings | B59: 22.57 | C59: 111.85 | D59: 150.84 | E59: 186.76 | F59: 249 | G59: 219.25 | H59: 107.71 | I59: 288.41 | J59: 419.44 | K59: 458.13
A60: Other Liabilities | B60: 1263.35 | C60: 1552.16 | D60: 2341.32 | E60: 2281.35 | F60: 2219.79 | G60: 2901.28 | H60: 3424.12 | I60: 3918.95 | J60: 4650.16 | K60: 5419.79
A61: Total | B61: 4939.01 | C61: 7009.08 | D61: 9522.23 | E61: 11386.83 | F61: 12449.72 | G61: 14558.61 | H61: 16139.83 | I61: 19197.64 | J61: 23115.13 | K61: 27174.41
...

Sheet Cash Flow Statement
C2: 41609 | D2: 41974 | E2: 42430 | F2: 42795 | G2: 43160 | H2: 43525 | I2: 43891 | J2: 44256 | K2: 44621 | L2: 44986 | M2: 45352 | N2: 45717
B3: Cash from Operating Activity - | C3: 716 | D3: 1047 | E3: 1463 | F3: 1708 | G3: 2482 | H3: 1575 | I3: 1694 | J3: 1691 | K3: 1527 | L3: 2823 | M3: 3724 | N3: 3980
B4: Profit from operations | C4: 718 | D4: 1126 | E4: 1719 | F4: 2196 | G4: 2851 | H4: 2941 | I4: 2236 | J4: 1912 | K4: 2172 | L4: 3527 | M4: 4404 | N4: 4849
B5: Receivables | C5: -67 | D5: -50 | E5: -22 | F5: -17 | G5: -18 | H5: -18 | I5: 0 | J5: -73 | K5: -147 | L5: -59 | M5: -5 | N5: -176
B6: Inventory | C6: -38 | D6: -119 | E6: -104 | F6: -28 | G6: -59 | H6: -239 | I6: 61 | J6: -302 | K6: -258 | L6: -146 | M6: -131 | N6: -154
B7: Payables | C7: 237 | D7: 321 | E7: 241 | F7: 110 | G7: 407 | H7: 62 | I7: -235 | J7: 495 | K7: 283 | L7: 22 | M7: 304 | N7: 440
B8: Loans Advances | C8: -20 | D8: -103 | E8: -12 | F8: 6 | G8: 0 | H8: -1 | I8: 1 | J8: 0 | K8: 0 | L8: 0 | M8: 0 | N8: 0
B9: Other WC items | C9: 37 | D9: 152 | E9: 160 | F9: 92 | G9: 109 | H9: -262 | I9: 259 | J9: 115 | K9: -10 | L9: 249 | M9: 220 | N9: 101
B10: Working capital changes | C10: 149 | D10: 202 | E10: 263 | F10: 163 | G10: 438 | H10: -457 | I10: 86 | J10: 235 | K10: -131 | L10: 66 | M10: 388 | N10: 211
B11: Direct taxes | C11: -150 | D11: -281 | E11: -519 | F11: -652 | G11: -807 | H11: -908 | I11: -628 | J11: -457 | K11: -514 | L11: -770 | M11: -1068 | N11: -1080
B12: Cash from Investing Activity - | C12: -790 | D12: -1214 | E12: -1001 | F12: -1744 | G12: -2145 | H12: -660 | I12: -1508 | J12: -1625 | K12: -983 | L12: -2397 | M12: -2834 | N12: -2461
B13: Fixed assets purchased | C13: -712 | D13: -972 | E13: -510 | F13: -548 | G13: -748 | H13: -792 | I13: -546 | J13: -532 | K13: -641 | L13: -682 | M13: -819 | N13: -1039
B14: Fixed assets sold | C14: 7 | D14: 4 | E14: 1 | F14: 1 | G14: 3 | H14: 2 | I14: 1 | J14: 17 | K14: 2 | L14: 9 | M14: 4 | N14: 11
... B29: Net Cash Flow | C29: -121 | D29: -329 | E29: -4 | F29: -10 | G29: 75 | H29: 623 | I29: -673 | J29: 51 | K29: -50 | L29: 8 | M29: 45 | N29: 121
